
CommandNotFoundError: Your shell has not been properly configured to use 'conda activate'.
To initialize your shell, run

    $ conda init <SHELL_NAME>

Currently supported shells are:
  - bash
  - fish
  - tcsh
  - xonsh
  - zsh
  - powershell

See 'conda init --help' for more information and options.

IMPORTANT: You may need to close and restart your shell after running 'conda init'.


------------ Options -------------
batchSize: 4
beta1: 0.5
checkpoints_dir: ./checkpoints
clothlmg2: False
clothrep: False
continue_train: True
data_type: 32
dataroot: ../../train_data/
debug: False
dense: False
densearms: False
densefull: False
denseone: False
denseplus: True
densestack: False
display_freq: 10
display_winsize: 512
fineSize: 512
gpu_ids: [0, 1, 2, 3]
input_nc: 3
isTrain: True
label_nc: 20
lambda_feat: 10.0
lambda_flm: 1
landmarks: True
loadSize: 512
load_pretrain: 
lr: 0.0002
max_dataset_size: inf
mesh: False
mesh_g: False
model: pix2pixHD
nThreads: 2
n_blocks_global: 4
n_blocks_local: 3
n_downsample_global: 4
n_layers_D: 3
n_local_enhancers: 1
name: denseplus_flm_nobodyseg_nopose
ndf: 64
neck: False
netG: global
ngf: 64
niter: 10
niter_decay: 10
niter_fix_global: 0
no_flip: False
no_ganFeat_loss: False
no_html: False
no_lsgan: False
no_vgg_loss: False
nobodyseg: True
nocollar: False
noopenpose: True
norm: instance
num_D: 2
output_nc: 3
pants: False
phase: train
pool_size: 0
print_freq: 10
resize_or_crop: scale_width
save_epoch_freq: 5
save_latest_freq: 20
serial_batches: False
tf_log: False
transfer: False
use_dropout: False
verbose: False
which_epoch: latest
-------------- End ----------------
Resuming from epoch 13 at iteration 3980
CustomDatasetDataLoader
dataset [AlignedDataset] was created
../../train_data/train_label label
../../train_data/train_label label
../../train_data/train_img img
../../train_data/train_img img
../../train_data/train_edge edge
../../train_data/train_edge edge
../../train_data/train_mask mask
../../train_data/train_mask mask
../../train_data/train_colormask colormask
../../train_data/train_colormask colormask
../../train_data/train_color color
../../train_data/train_color color
../../train_data/train_seg seg
../../train_data/train_seg seg
../../train_data/train_mesh mesh
../../train_data/train_mesh mesh
../../train_data/train_dense dense
../../train_data/train_dense dense
../../train_data/train_landmarks_cloth cloth
../../train_data/train_landmarks_cloth cloth
../../train_data/train_landmarks_person person
../../train_data/train_landmarks_person person
#training images = 14220
Traceback (most recent call last):
  File "train.py", line 171, in <module>
    model = create_model(opt)
  File "/work/gcrepaldi/vton/acgpn_custom/ACGPN_train/models/models.py", line 8, in create_model
    from .pix2pixHD_model import Pix2PixHDModel, InferenceModel
  File "/work/gcrepaldi/vton/acgpn_custom/ACGPN_train/models/pix2pixHD_model.py", line 133
    if self.opt.clothlmg2# or self.opt.denseplus:
                                                ^
SyntaxError: invalid syntax

If you suspect this is an IPython 7.12.0 bug, please report it at:
    https://github.com/ipython/ipython/issues
or send an email to the mailing list at ipython-dev@python.org

You can print a more detailed traceback right now with "%tb", or use "%debug"
to interactively debug it.

Extra-detailed tracebacks for bug-reporting purposes can be enabled via:
    %config Application.verbose_crash=True

